[2025-03-24T09:48:24.570+0000] {local_task_job_runner.py:123} INFO - ::group::Pre task execution logs
[2025-03-24T09:48:24.589+0000] {taskinstance.py:2614} INFO - Dependencies all met for dep_context=non-requeueable deps ti=<TaskInstance: data_eng_dag_etl.process_snowflake_file manual__2025-03-24T09:48:21.375632+00:00 [queued]>
[2025-03-24T09:48:24.600+0000] {taskinstance.py:2614} INFO - Dependencies all met for dep_context=requeueable deps ti=<TaskInstance: data_eng_dag_etl.process_snowflake_file manual__2025-03-24T09:48:21.375632+00:00 [queued]>
[2025-03-24T09:48:24.601+0000] {taskinstance.py:2867} INFO - Starting attempt 1 of 1
[2025-03-24T09:48:24.618+0000] {taskinstance.py:2890} INFO - Executing <Task(PythonOperator): process_snowflake_file> on 2025-03-24 09:48:21.375632+00:00
[2025-03-24T09:48:24.623+0000] {warnings.py:112} WARNING - /home/***/.local/lib/python3.12/site-packages/***/task/task_runner/standard_task_runner.py:70: DeprecationWarning: This process (pid=143) is multi-threaded, use of fork() may lead to deadlocks in the child.
  pid = os.fork()

[2025-03-24T09:48:24.624+0000] {standard_task_runner.py:72} INFO - Started process 145 to run task
[2025-03-24T09:48:24.626+0000] {standard_task_runner.py:104} INFO - Running: ['***', 'tasks', 'run', 'data_eng_dag_etl', 'process_snowflake_file', 'manual__2025-03-24T09:48:21.375632+00:00', '--job-id', '38', '--raw', '--subdir', 'DAGS_FOLDER/data-eng-dag-etl/dag.py', '--cfg-path', '/tmp/tmparsgz9fs']
[2025-03-24T09:48:24.628+0000] {standard_task_runner.py:105} INFO - Job 38: Subtask process_snowflake_file
[2025-03-24T09:48:24.670+0000] {task_command.py:467} INFO - Running <TaskInstance: data_eng_dag_etl.process_snowflake_file manual__2025-03-24T09:48:21.375632+00:00 [running]> on host 41479ed95271
[2025-03-24T09:48:24.753+0000] {taskinstance.py:3134} INFO - Exporting env vars: AIRFLOW_CTX_DAG_OWNER='***' AIRFLOW_CTX_DAG_ID='data_eng_dag_etl' AIRFLOW_CTX_TASK_ID='process_snowflake_file' AIRFLOW_CTX_EXECUTION_DATE='2025-03-24T09:48:21.375632+00:00' AIRFLOW_CTX_TRY_NUMBER='1' AIRFLOW_CTX_DAG_RUN_ID='manual__2025-03-24T09:48:21.375632+00:00'
[2025-03-24T09:48:24.754+0000] {taskinstance.py:732} INFO - ::endgroup::
[2025-03-24T09:48:24.793+0000] {base.py:84} INFO - Retrieving connection 'snowflake_default'
[2025-03-24T09:48:24.794+0000] {connection.py:424} INFO - Snowflake Connector for Python Version: 3.13.2, Python Version: 3.12.9, Platform: Linux-6.8.0-52-generic-x86_64-with-glibc2.36
[2025-03-24T09:48:24.797+0000] {connection.py:1213} INFO - Connecting to GLOBAL Snowflake domain
[2025-03-24T09:48:24.797+0000] {connection.py:1295} INFO - This connection is in OCSP Fail Open Mode. TLS Certificates would be checked for validity and revocation status. Any other Certificate Revocation related exceptions or OCSP Responder failures would be disregarded in favor of connectivity.
[2025-03-24T09:48:31.593+0000] {sql.py:511} INFO - Running statement: LIST @RECRUITMENT_DB.PUBLIC.S3_FOLDER;, parameters: None
[2025-03-24T09:48:31.972+0000] {sql.py:520} INFO - Rows affected: 1
[2025-03-24T09:48:31.974+0000] {warnings.py:112} WARNING - /home/***/.local/lib/python3.12/site-packages/***/providers/snowflake/hooks/snowflake.py:468: DeprecationWarning: Import of fetch_one_handler from the '***.providers.common.sql.hooks' module is deprecated and will
be removed in the future. Please import it from '***.providers.common.sql.hooks.handlers'.
  result = self._make_common_data_structure(handler(cur))  # type: ignore[attr-defined]

[2025-03-24T09:48:31.977+0000] {warnings.py:112} WARNING - /home/***/.local/lib/python3.12/site-packages/***/providers/snowflake/hooks/snowflake.py:469: DeprecationWarning: Import of return_single_query_results from the '***.providers.common.sql.hooks' module is deprecated and will
be removed in the future. Please import it from '***.providers.common.sql.hooks.handlers'.
  if return_single_query_results(sql, return_last, split_statements):

[2025-03-24T09:48:31.979+0000] {snowflake.py:477} INFO - Rows affected: 1
[2025-03-24T09:48:31.979+0000] {snowflake.py:478} INFO - Snowflake query id: 01bb382c-0907-d01f-006a-f2030076a102
[2025-03-24T09:48:32.272+0000] {connection.py:803} INFO - closed
[2025-03-24T09:48:32.517+0000] {connection.py:809} INFO - No async queries seem to be running, deleting session
[2025-03-24T09:48:32.777+0000] {warnings.py:112} WARNING - /home/***/.local/lib/python3.12/site-packages/***/providers/snowflake/hooks/snowflake.py:487: DeprecationWarning: Import of return_single_query_results from the '***.providers.common.sql.hooks' module is deprecated and will
be removed in the future. Please import it from '***.providers.common.sql.hooks.handlers'.
  if return_single_query_results(sql, return_last, split_statements):

[2025-03-24T09:48:32.778+0000] {logging_mixin.py:190} INFO - Arquivos encontrados: ('s3://iw-recruiting-dataset/flights.gz', 48835247, '5e3e1b99afa2998e7459bab2cdc2ee90-3', 'Wed, 6 Jul 2022 01:43:24 GMT')
[2025-03-24T09:48:32.779+0000] {logging_mixin.py:190} INFO - Arquivo encontrado: s3://iw-recruiting-dataset/flights.gz
[2025-03-24T09:48:32.790+0000] {base.py:84} INFO - Retrieving connection 'snowflake_default'
[2025-03-24T09:48:32.791+0000] {connection.py:424} INFO - Snowflake Connector for Python Version: 3.13.2, Python Version: 3.12.9, Platform: Linux-6.8.0-52-generic-x86_64-with-glibc2.36
[2025-03-24T09:48:32.792+0000] {connection.py:1213} INFO - Connecting to GLOBAL Snowflake domain
[2025-03-24T09:48:32.793+0000] {connection.py:1295} INFO - This connection is in OCSP Fail Open Mode. TLS Certificates would be checked for validity and revocation status. Any other Certificate Revocation related exceptions or OCSP Responder failures would be disregarded in favor of connectivity.
[2025-03-24T09:48:34.119+0000] {sql.py:511} INFO - Running statement: GET s3://iw-recruiting-dataset/flights.gz file:///tmp/file.zip, parameters: None
[2025-03-24T09:48:34.434+0000] {connection.py:803} INFO - closed
[2025-03-24T09:48:34.733+0000] {connection.py:809} INFO - No async queries seem to be running, deleting session
[2025-03-24T09:48:35.043+0000] {taskinstance.py:3313} ERROR - Task failed with exception
Traceback (most recent call last):
  File "/home/airflow/.local/lib/python3.12/site-packages/airflow/models/taskinstance.py", line 768, in _execute_task
    result = _execute_callable(context=context, **execute_callable_kwargs)
             ^^^^^^^^^^^^^^^^^^^^^^^^^^^^^^^^^^^^^^^^^^^^^^^^^^^^^^^^^^^^^
  File "/home/airflow/.local/lib/python3.12/site-packages/airflow/models/taskinstance.py", line 734, in _execute_callable
    return ExecutionCallableRunner(
           ^^^^^^^^^^^^^^^^^^^^^^^^
  File "/home/airflow/.local/lib/python3.12/site-packages/airflow/utils/operator_helpers.py", line 252, in run
    return self.func(*args, **kwargs)
           ^^^^^^^^^^^^^^^^^^^^^^^^^^
  File "/home/airflow/.local/lib/python3.12/site-packages/airflow/models/baseoperator.py", line 424, in wrapper
    return func(self, *args, **kwargs)
           ^^^^^^^^^^^^^^^^^^^^^^^^^^^
  File "/home/airflow/.local/lib/python3.12/site-packages/airflow/operators/python.py", line 238, in execute
    return_value = self.execute_callable()
                   ^^^^^^^^^^^^^^^^^^^^^^^
  File "/home/airflow/.local/lib/python3.12/site-packages/airflow/operators/python.py", line 256, in execute_callable
    return runner.run(*self.op_args, **self.op_kwargs)
           ^^^^^^^^^^^^^^^^^^^^^^^^^^^^^^^^^^^^^^^^^^^
  File "/home/airflow/.local/lib/python3.12/site-packages/airflow/utils/operator_helpers.py", line 252, in run
    return self.func(*args, **kwargs)
           ^^^^^^^^^^^^^^^^^^^^^^^^^^
  File "/opt/airflow/dags/data-eng-dag-etl/dag.py", line 47, in process_snowflake_file
    hook.run(sql_get)
  File "/home/airflow/.local/lib/python3.12/site-packages/airflow/providers/snowflake/hooks/snowflake.py", line 465, in run
    self._run_command(cur, sql_statement, parameters)  # type: ignore[attr-defined]
    ^^^^^^^^^^^^^^^^^^^^^^^^^^^^^^^^^^^^^^^^^^^^^^^^^
  File "/home/airflow/.local/lib/python3.12/site-packages/airflow/providers/common/sql/hooks/sql.py", line 516, in _run_command
    cur.execute(sql_statement)
  File "/home/airflow/.local/lib/python3.12/site-packages/snowflake/connector/cursor.py", line 1103, in execute
    Error.errorhandler_wrapper(self.connection, self, error_class, errvalue)
  File "/home/airflow/.local/lib/python3.12/site-packages/snowflake/connector/errors.py", line 283, in errorhandler_wrapper
    handed_over = Error.hand_to_other_handler(
                  ^^^^^^^^^^^^^^^^^^^^^^^^^^^^
  File "/home/airflow/.local/lib/python3.12/site-packages/snowflake/connector/errors.py", line 338, in hand_to_other_handler
    cursor.errorhandler(connection, cursor, error_class, error_value)
  File "/home/airflow/.local/lib/python3.12/site-packages/snowflake/connector/errors.py", line 214, in default_errorhandler
    raise error_class(
snowflake.connector.errors.ProgrammingError: 001011 (42601): 01bb382c-0907-c6ea-006a-f2030076999e: SQL compilation error:
invalid URL prefix found in: 's3://iw-recruiting-dataset/flights.gz'
[2025-03-24T09:48:35.063+0000] {taskinstance.py:1226} INFO - Marking task as FAILED. dag_id=data_eng_dag_etl, task_id=process_snowflake_file, run_id=manual__2025-03-24T09:48:21.375632+00:00, execution_date=20250324T094821, start_date=20250324T094824, end_date=20250324T094835
[2025-03-24T09:48:35.102+0000] {taskinstance.py:341} INFO - ::group::Post task execution logs
[2025-03-24T09:48:35.102+0000] {standard_task_runner.py:124} ERROR - Failed to execute job 38 for task process_snowflake_file (001011 (42601): 01bb382c-0907-c6ea-006a-f2030076999e: SQL compilation error:
invalid URL prefix found in: 's3://iw-recruiting-dataset/flights.gz'; 145)
Traceback (most recent call last):
  File "/home/airflow/.local/lib/python3.12/site-packages/airflow/task/task_runner/standard_task_runner.py", line 117, in _start_by_fork
    ret = args.func(args, dag=self.dag)
          ^^^^^^^^^^^^^^^^^^^^^^^^^^^^^
  File "/home/airflow/.local/lib/python3.12/site-packages/airflow/cli/cli_config.py", line 49, in command
    return func(*args, **kwargs)
           ^^^^^^^^^^^^^^^^^^^^^
  File "/home/airflow/.local/lib/python3.12/site-packages/airflow/utils/cli.py", line 116, in wrapper
    return f(*args, **kwargs)
           ^^^^^^^^^^^^^^^^^^
  File "/home/airflow/.local/lib/python3.12/site-packages/airflow/cli/commands/task_command.py", line 483, in task_run
    task_return_code = _run_task_by_selected_method(args, _dag, ti)
                       ^^^^^^^^^^^^^^^^^^^^^^^^^^^^^^^^^^^^^^^^^^^^
  File "/home/airflow/.local/lib/python3.12/site-packages/airflow/cli/commands/task_command.py", line 256, in _run_task_by_selected_method
    return _run_raw_task(args, ti)
           ^^^^^^^^^^^^^^^^^^^^^^^
  File "/home/airflow/.local/lib/python3.12/site-packages/airflow/cli/commands/task_command.py", line 341, in _run_raw_task
    return ti._run_raw_task(
           ^^^^^^^^^^^^^^^^^
  File "/home/airflow/.local/lib/python3.12/site-packages/airflow/utils/session.py", line 97, in wrapper
    return func(*args, session=session, **kwargs)
           ^^^^^^^^^^^^^^^^^^^^^^^^^^^^^^^^^^^^^^
  File "/home/airflow/.local/lib/python3.12/site-packages/airflow/models/taskinstance.py", line 3006, in _run_raw_task
    return _run_raw_task(
           ^^^^^^^^^^^^^^
  File "/home/airflow/.local/lib/python3.12/site-packages/airflow/models/taskinstance.py", line 274, in _run_raw_task
    TaskInstance._execute_task_with_callbacks(
  File "/home/airflow/.local/lib/python3.12/site-packages/airflow/models/taskinstance.py", line 3161, in _execute_task_with_callbacks
    result = self._execute_task(context, task_orig)
             ^^^^^^^^^^^^^^^^^^^^^^^^^^^^^^^^^^^^^^
  File "/home/airflow/.local/lib/python3.12/site-packages/airflow/models/taskinstance.py", line 3185, in _execute_task
    return _execute_task(self, context, task_orig)
           ^^^^^^^^^^^^^^^^^^^^^^^^^^^^^^^^^^^^^^^
  File "/home/airflow/.local/lib/python3.12/site-packages/airflow/models/taskinstance.py", line 768, in _execute_task
    result = _execute_callable(context=context, **execute_callable_kwargs)
             ^^^^^^^^^^^^^^^^^^^^^^^^^^^^^^^^^^^^^^^^^^^^^^^^^^^^^^^^^^^^^
  File "/home/airflow/.local/lib/python3.12/site-packages/airflow/models/taskinstance.py", line 734, in _execute_callable
    return ExecutionCallableRunner(
           ^^^^^^^^^^^^^^^^^^^^^^^^
  File "/home/airflow/.local/lib/python3.12/site-packages/airflow/utils/operator_helpers.py", line 252, in run
    return self.func(*args, **kwargs)
           ^^^^^^^^^^^^^^^^^^^^^^^^^^
  File "/home/airflow/.local/lib/python3.12/site-packages/airflow/models/baseoperator.py", line 424, in wrapper
    return func(self, *args, **kwargs)
           ^^^^^^^^^^^^^^^^^^^^^^^^^^^
  File "/home/airflow/.local/lib/python3.12/site-packages/airflow/operators/python.py", line 238, in execute
    return_value = self.execute_callable()
                   ^^^^^^^^^^^^^^^^^^^^^^^
  File "/home/airflow/.local/lib/python3.12/site-packages/airflow/operators/python.py", line 256, in execute_callable
    return runner.run(*self.op_args, **self.op_kwargs)
           ^^^^^^^^^^^^^^^^^^^^^^^^^^^^^^^^^^^^^^^^^^^
  File "/home/airflow/.local/lib/python3.12/site-packages/airflow/utils/operator_helpers.py", line 252, in run
    return self.func(*args, **kwargs)
           ^^^^^^^^^^^^^^^^^^^^^^^^^^
  File "/opt/airflow/dags/data-eng-dag-etl/dag.py", line 47, in process_snowflake_file
    hook.run(sql_get)
  File "/home/airflow/.local/lib/python3.12/site-packages/airflow/providers/snowflake/hooks/snowflake.py", line 465, in run
    self._run_command(cur, sql_statement, parameters)  # type: ignore[attr-defined]
    ^^^^^^^^^^^^^^^^^^^^^^^^^^^^^^^^^^^^^^^^^^^^^^^^^
  File "/home/airflow/.local/lib/python3.12/site-packages/airflow/providers/common/sql/hooks/sql.py", line 516, in _run_command
    cur.execute(sql_statement)
  File "/home/airflow/.local/lib/python3.12/site-packages/snowflake/connector/cursor.py", line 1103, in execute
    Error.errorhandler_wrapper(self.connection, self, error_class, errvalue)
  File "/home/airflow/.local/lib/python3.12/site-packages/snowflake/connector/errors.py", line 283, in errorhandler_wrapper
    handed_over = Error.hand_to_other_handler(
                  ^^^^^^^^^^^^^^^^^^^^^^^^^^^^
  File "/home/airflow/.local/lib/python3.12/site-packages/snowflake/connector/errors.py", line 338, in hand_to_other_handler
    cursor.errorhandler(connection, cursor, error_class, error_value)
  File "/home/airflow/.local/lib/python3.12/site-packages/snowflake/connector/errors.py", line 214, in default_errorhandler
    raise error_class(
snowflake.connector.errors.ProgrammingError: 001011 (42601): 01bb382c-0907-c6ea-006a-f2030076999e: SQL compilation error:
invalid URL prefix found in: 's3://iw-recruiting-dataset/flights.gz'
[2025-03-24T09:48:35.124+0000] {local_task_job_runner.py:266} INFO - Task exited with return code 1
[2025-03-24T09:48:35.151+0000] {taskinstance.py:3901} INFO - 0 downstream tasks scheduled from follow-on schedule check
[2025-03-24T09:48:35.155+0000] {local_task_job_runner.py:245} INFO - ::endgroup::
