[2025-03-24T16:08:08.485+0000] {local_task_job_runner.py:123} INFO - ::group::Pre task execution logs
[2025-03-24T16:08:08.510+0000] {taskinstance.py:2614} INFO - Dependencies all met for dep_context=non-requeueable deps ti=<TaskInstance: data_eng_dag_etl.creating_ddl_task manual__2025-03-24T16:08:04.700061+00:00 [queued]>
[2025-03-24T16:08:08.522+0000] {taskinstance.py:2614} INFO - Dependencies all met for dep_context=requeueable deps ti=<TaskInstance: data_eng_dag_etl.creating_ddl_task manual__2025-03-24T16:08:04.700061+00:00 [queued]>
[2025-03-24T16:08:08.522+0000] {taskinstance.py:2867} INFO - Starting attempt 1 of 1
[2025-03-24T16:08:08.534+0000] {taskinstance.py:2890} INFO - Executing <Task(PythonOperator): creating_ddl_task> on 2025-03-24 16:08:04.700061+00:00
[2025-03-24T16:08:08.539+0000] {warnings.py:112} WARNING - /home/***/.local/lib/python3.12/site-packages/***/task/task_runner/standard_task_runner.py:70: DeprecationWarning: This process (pid=115) is multi-threaded, use of fork() may lead to deadlocks in the child.
  pid = os.fork()

[2025-03-24T16:08:08.539+0000] {standard_task_runner.py:72} INFO - Started process 117 to run task
[2025-03-24T16:08:08.540+0000] {standard_task_runner.py:104} INFO - Running: ['***', 'tasks', 'run', 'data_eng_dag_etl', 'creating_ddl_task', 'manual__2025-03-24T16:08:04.700061+00:00', '--job-id', '85', '--raw', '--subdir', 'DAGS_FOLDER/data-eng-dag-etl/dag.py', '--cfg-path', '/tmp/tmp3yrj74pt']
[2025-03-24T16:08:08.542+0000] {standard_task_runner.py:105} INFO - Job 85: Subtask creating_ddl_task
[2025-03-24T16:08:08.601+0000] {task_command.py:467} INFO - Running <TaskInstance: data_eng_dag_etl.creating_ddl_task manual__2025-03-24T16:08:04.700061+00:00 [running]> on host ce27fa8c169a
[2025-03-24T16:08:08.709+0000] {taskinstance.py:3134} INFO - Exporting env vars: AIRFLOW_CTX_DAG_EMAIL='celulardaveve@gmail.com' AIRFLOW_CTX_DAG_OWNER='Veronica Sa' AIRFLOW_CTX_DAG_ID='data_eng_dag_etl' AIRFLOW_CTX_TASK_ID='creating_ddl_task' AIRFLOW_CTX_EXECUTION_DATE='2025-03-24T16:08:04.700061+00:00' AIRFLOW_CTX_TRY_NUMBER='1' AIRFLOW_CTX_DAG_RUN_ID='manual__2025-03-24T16:08:04.700061+00:00'
[2025-03-24T16:08:08.711+0000] {taskinstance.py:732} INFO - ::endgroup::
[2025-03-24T16:08:08.746+0000] {base.py:84} INFO - Retrieving connection 'snowflake_default'
[2025-03-24T16:08:08.748+0000] {connection.py:424} INFO - Snowflake Connector for Python Version: 3.13.2, Python Version: 3.12.9, Platform: Linux-6.8.0-52-generic-x86_64-with-glibc2.36
[2025-03-24T16:08:08.752+0000] {connection.py:1213} INFO - Connecting to GLOBAL Snowflake domain
[2025-03-24T16:08:08.752+0000] {connection.py:1295} INFO - This connection is in OCSP Fail Open Mode. TLS Certificates would be checked for validity and revocation status. Any other Certificate Revocation related exceptions or OCSP Responder failures would be disregarded in favor of connectivity.
[2025-03-24T16:08:11.927+0000] {sql.py:511} INFO - Running statement: SELECT *
    FROM TABLE(
    INFER_SCHEMA(
      LOCATION=>'@RECRUITMENT_DB.PUBLIC.S3_FOLDER/flights.gz'
      , FILE_FORMAT=>'my_csv_format'
      )
    );, parameters: None
[2025-03-24T16:08:18.201+0000] {sql.py:520} INFO - Rows affected: 1
[2025-03-24T16:08:18.202+0000] {warnings.py:112} WARNING - /home/***/.local/lib/python3.12/site-packages/***/providers/snowflake/hooks/snowflake.py:468: DeprecationWarning: Import of fetch_all_handler from the '***.providers.common.sql.hooks' module is deprecated and will
be removed in the future. Please import it from '***.providers.common.sql.hooks.handlers'.
  result = self._make_common_data_structure(handler(cur))  # type: ignore[attr-defined]

[2025-03-24T16:08:18.206+0000] {warnings.py:112} WARNING - /home/***/.local/lib/python3.12/site-packages/***/providers/snowflake/hooks/snowflake.py:469: DeprecationWarning: Import of return_single_query_results from the '***.providers.common.sql.hooks' module is deprecated and will
be removed in the future. Please import it from '***.providers.common.sql.hooks.handlers'.
  if return_single_query_results(sql, return_last, split_statements):

[2025-03-24T16:08:18.208+0000] {snowflake.py:477} INFO - Rows affected: 1
[2025-03-24T16:08:18.208+0000] {snowflake.py:478} INFO - Snowflake query id: 01bb39a8-0907-dcc6-006a-f2030076d08e
[2025-03-24T16:08:18.626+0000] {connection.py:803} INFO - closed
[2025-03-24T16:08:19.005+0000] {connection.py:809} INFO - No async queries seem to be running, deleting session
[2025-03-24T16:08:19.344+0000] {warnings.py:112} WARNING - /home/***/.local/lib/python3.12/site-packages/***/providers/snowflake/hooks/snowflake.py:487: DeprecationWarning: Import of return_single_query_results from the '***.providers.common.sql.hooks' module is deprecated and will
be removed in the future. Please import it from '***.providers.common.sql.hooks.handlers'.
  if return_single_query_results(sql, return_last, split_statements):

[2025-03-24T16:08:19.345+0000] {logging_mixin.py:190} INFO - ##################################
[2025-03-24T16:08:19.345+0000] {logging_mixin.py:190} INFO - String with all columns
[2025-03-24T16:08:19.346+0000] {logging_mixin.py:190} INFO - [('TRANSACTIONID|FLIGHTDATE|AIRLINECODE|AIRLINENAME|TAILNUM|FLIGHTNUM|ORIGINAIRPORTCODE|ORIGAIRPORTNAME|ORIGINCITYNAME|ORIGINSTATE|ORIGINSTATENAME|DESTAIRPORTCODE|DESTAIRPORTNAME|DESTCITYNAME|DESTSTATE|DESTSTATENAME|CRSDEPTIME|DEPTIME|DEPDELAY|TAXIOUT|WHEELSOFF|WHEELSON|TAXIIN|CRSARRTIME|ARRTIME|ARRDELAY|CRSELAPSEDTIME|ACTUALELAPSEDTIME|CANCELLED|DIVERTED|DISTANCE', 'TEXT', True, '$1::TEXT', 'flights.gz', 0)]
[2025-03-24T16:08:19.346+0000] {taskinstance.py:3313} ERROR - Task failed with exception
Traceback (most recent call last):
  File "/home/airflow/.local/lib/python3.12/site-packages/airflow/models/taskinstance.py", line 768, in _execute_task
    result = _execute_callable(context=context, **execute_callable_kwargs)
             ^^^^^^^^^^^^^^^^^^^^^^^^^^^^^^^^^^^^^^^^^^^^^^^^^^^^^^^^^^^^^
  File "/home/airflow/.local/lib/python3.12/site-packages/airflow/models/taskinstance.py", line 734, in _execute_callable
    return ExecutionCallableRunner(
           ^^^^^^^^^^^^^^^^^^^^^^^^
  File "/home/airflow/.local/lib/python3.12/site-packages/airflow/utils/operator_helpers.py", line 252, in run
    return self.func(*args, **kwargs)
           ^^^^^^^^^^^^^^^^^^^^^^^^^^
  File "/home/airflow/.local/lib/python3.12/site-packages/airflow/models/baseoperator.py", line 424, in wrapper
    return func(self, *args, **kwargs)
           ^^^^^^^^^^^^^^^^^^^^^^^^^^^
  File "/home/airflow/.local/lib/python3.12/site-packages/airflow/operators/python.py", line 238, in execute
    return_value = self.execute_callable()
                   ^^^^^^^^^^^^^^^^^^^^^^^
  File "/home/airflow/.local/lib/python3.12/site-packages/airflow/operators/python.py", line 256, in execute_callable
    return runner.run(*self.op_args, **self.op_kwargs)
           ^^^^^^^^^^^^^^^^^^^^^^^^^^^^^^^^^^^^^^^^^^^
  File "/home/airflow/.local/lib/python3.12/site-packages/airflow/utils/operator_helpers.py", line 252, in run
    return self.func(*args, **kwargs)
           ^^^^^^^^^^^^^^^^^^^^^^^^^^
  File "/opt/airflow/dags/data-eng-dag-etl/dag.py", line 50, in creating_ddl
    column_name = input_str[0].split('|')
                  ^^^^^^^^^^^^^^^^^^
AttributeError: 'tuple' object has no attribute 'split'
[2025-03-24T16:08:19.359+0000] {taskinstance.py:1226} INFO - Marking task as FAILED. dag_id=data_eng_dag_etl, task_id=creating_ddl_task, run_id=manual__2025-03-24T16:08:04.700061+00:00, execution_date=20250324T160804, start_date=20250324T160808, end_date=20250324T160819
[2025-03-24T16:08:19.377+0000] {warnings.py:112} WARNING - /home/***/.local/lib/python3.12/site-packages/***/utils/email.py:155: RemovedInAirflow3Warning: Fetching SMTP credentials from configuration variables will be deprecated in a future release. Please set credentials using a connection instead.
  send_mime_email(e_from=mail_from, e_to=recipients, mime_msg=msg, conn_id=conn_id, dryrun=dryrun)

[2025-03-24T16:08:19.378+0000] {configuration.py:1074} WARNING - section/key [smtp/smtp_user] not found in config
[2025-03-24T16:08:19.378+0000] {email.py:272} INFO - Email alerting: attempt 1
[2025-03-24T16:08:19.389+0000] {configuration.py:1074} WARNING - section/key [smtp/smtp_user] not found in config
[2025-03-24T16:08:19.390+0000] {email.py:272} INFO - Email alerting: attempt 1
[2025-03-24T16:08:19.391+0000] {taskinstance.py:1235} ERROR - Failed to send email to: ['celulardaveve@gmail.com']
Traceback (most recent call last):
  File "/home/airflow/.local/lib/python3.12/site-packages/airflow/models/taskinstance.py", line 274, in _run_raw_task
    TaskInstance._execute_task_with_callbacks(
  File "/home/airflow/.local/lib/python3.12/site-packages/airflow/models/taskinstance.py", line 3161, in _execute_task_with_callbacks
    result = self._execute_task(context, task_orig)
             ^^^^^^^^^^^^^^^^^^^^^^^^^^^^^^^^^^^^^^
  File "/home/airflow/.local/lib/python3.12/site-packages/airflow/models/taskinstance.py", line 3185, in _execute_task
    return _execute_task(self, context, task_orig)
           ^^^^^^^^^^^^^^^^^^^^^^^^^^^^^^^^^^^^^^^
  File "/home/airflow/.local/lib/python3.12/site-packages/airflow/models/taskinstance.py", line 768, in _execute_task
    result = _execute_callable(context=context, **execute_callable_kwargs)
             ^^^^^^^^^^^^^^^^^^^^^^^^^^^^^^^^^^^^^^^^^^^^^^^^^^^^^^^^^^^^^
  File "/home/airflow/.local/lib/python3.12/site-packages/airflow/models/taskinstance.py", line 734, in _execute_callable
    return ExecutionCallableRunner(
           ^^^^^^^^^^^^^^^^^^^^^^^^
  File "/home/airflow/.local/lib/python3.12/site-packages/airflow/utils/operator_helpers.py", line 252, in run
    return self.func(*args, **kwargs)
           ^^^^^^^^^^^^^^^^^^^^^^^^^^
  File "/home/airflow/.local/lib/python3.12/site-packages/airflow/models/baseoperator.py", line 424, in wrapper
    return func(self, *args, **kwargs)
           ^^^^^^^^^^^^^^^^^^^^^^^^^^^
  File "/home/airflow/.local/lib/python3.12/site-packages/airflow/operators/python.py", line 238, in execute
    return_value = self.execute_callable()
                   ^^^^^^^^^^^^^^^^^^^^^^^
  File "/home/airflow/.local/lib/python3.12/site-packages/airflow/operators/python.py", line 256, in execute_callable
    return runner.run(*self.op_args, **self.op_kwargs)
           ^^^^^^^^^^^^^^^^^^^^^^^^^^^^^^^^^^^^^^^^^^^
  File "/home/airflow/.local/lib/python3.12/site-packages/airflow/utils/operator_helpers.py", line 252, in run
    return self.func(*args, **kwargs)
           ^^^^^^^^^^^^^^^^^^^^^^^^^^
  File "/opt/airflow/dags/data-eng-dag-etl/dag.py", line 50, in creating_ddl
    column_name = input_str[0].split('|')
                  ^^^^^^^^^^^^^^^^^^
AttributeError: 'tuple' object has no attribute 'split'

During handling of the above exception, another exception occurred:

Traceback (most recent call last):
  File "/home/airflow/.local/lib/python3.12/site-packages/airflow/models/taskinstance.py", line 1443, in _email_alert
    send_email(task.email, subject, html_content)
  File "/home/airflow/.local/lib/python3.12/site-packages/airflow/utils/email.py", line 80, in send_email
    return backend(
           ^^^^^^^^
  File "/home/airflow/.local/lib/python3.12/site-packages/airflow/utils/email.py", line 155, in send_email_smtp
    send_mime_email(e_from=mail_from, e_to=recipients, mime_msg=msg, conn_id=conn_id, dryrun=dryrun)
  File "/home/airflow/.local/lib/python3.12/site-packages/airflow/utils/email.py", line 274, in send_mime_email
    smtp_conn = _get_smtp_connection(smtp_host, smtp_port, smtp_timeout, smtp_ssl)
                ^^^^^^^^^^^^^^^^^^^^^^^^^^^^^^^^^^^^^^^^^^^^^^^^^^^^^^^^^^^^^^^^^^
  File "/home/airflow/.local/lib/python3.12/site-packages/airflow/utils/email.py", line 318, in _get_smtp_connection
    return smtplib.SMTP(host=host, port=port, timeout=timeout)
           ^^^^^^^^^^^^^^^^^^^^^^^^^^^^^^^^^^^^^^^^^^^^^^^^^^^
  File "/usr/local/lib/python3.12/smtplib.py", line 255, in __init__
    (code, msg) = self.connect(host, port)
                  ^^^^^^^^^^^^^^^^^^^^^^^^
  File "/usr/local/lib/python3.12/smtplib.py", line 341, in connect
    self.sock = self._get_socket(host, port, self.timeout)
                ^^^^^^^^^^^^^^^^^^^^^^^^^^^^^^^^^^^^^^^^^^
  File "/usr/local/lib/python3.12/smtplib.py", line 312, in _get_socket
    return socket.create_connection((host, port), timeout,
           ^^^^^^^^^^^^^^^^^^^^^^^^^^^^^^^^^^^^^^^^^^^^^^^
  File "/usr/local/lib/python3.12/socket.py", line 865, in create_connection
    raise exceptions[0]
  File "/usr/local/lib/python3.12/socket.py", line 850, in create_connection
    sock.connect(sa)
ConnectionRefusedError: [Errno 111] Connection refused

During handling of the above exception, another exception occurred:

Traceback (most recent call last):
  File "/home/airflow/.local/lib/python3.12/site-packages/airflow/models/taskinstance.py", line 1233, in _handle_failure
    task_instance.email_alert(error, failure_context["task"])
  File "/home/airflow/.local/lib/python3.12/site-packages/airflow/models/taskinstance.py", line 3611, in email_alert
    _email_alert(task_instance=self, exception=exception, task=task)
  File "/home/airflow/.local/lib/python3.12/site-packages/airflow/models/taskinstance.py", line 1445, in _email_alert
    send_email(task.email, subject, html_content_err)
  File "/home/airflow/.local/lib/python3.12/site-packages/airflow/utils/email.py", line 80, in send_email
    return backend(
           ^^^^^^^^
  File "/home/airflow/.local/lib/python3.12/site-packages/airflow/utils/email.py", line 155, in send_email_smtp
    send_mime_email(e_from=mail_from, e_to=recipients, mime_msg=msg, conn_id=conn_id, dryrun=dryrun)
  File "/home/airflow/.local/lib/python3.12/site-packages/airflow/utils/email.py", line 274, in send_mime_email
    smtp_conn = _get_smtp_connection(smtp_host, smtp_port, smtp_timeout, smtp_ssl)
                ^^^^^^^^^^^^^^^^^^^^^^^^^^^^^^^^^^^^^^^^^^^^^^^^^^^^^^^^^^^^^^^^^^
  File "/home/airflow/.local/lib/python3.12/site-packages/airflow/utils/email.py", line 318, in _get_smtp_connection
    return smtplib.SMTP(host=host, port=port, timeout=timeout)
           ^^^^^^^^^^^^^^^^^^^^^^^^^^^^^^^^^^^^^^^^^^^^^^^^^^^
  File "/usr/local/lib/python3.12/smtplib.py", line 255, in __init__
    (code, msg) = self.connect(host, port)
                  ^^^^^^^^^^^^^^^^^^^^^^^^
  File "/usr/local/lib/python3.12/smtplib.py", line 341, in connect
    self.sock = self._get_socket(host, port, self.timeout)
                ^^^^^^^^^^^^^^^^^^^^^^^^^^^^^^^^^^^^^^^^^^
  File "/usr/local/lib/python3.12/smtplib.py", line 312, in _get_socket
    return socket.create_connection((host, port), timeout,
           ^^^^^^^^^^^^^^^^^^^^^^^^^^^^^^^^^^^^^^^^^^^^^^^
  File "/usr/local/lib/python3.12/socket.py", line 865, in create_connection
    raise exceptions[0]
  File "/usr/local/lib/python3.12/socket.py", line 850, in create_connection
    sock.connect(sa)
ConnectionRefusedError: [Errno 111] Connection refused
[2025-03-24T16:08:19.431+0000] {taskinstance.py:341} INFO - ::group::Post task execution logs
[2025-03-24T16:08:19.431+0000] {standard_task_runner.py:124} ERROR - Failed to execute job 85 for task creating_ddl_task ('tuple' object has no attribute 'split'; 117)
Traceback (most recent call last):
  File "/home/airflow/.local/lib/python3.12/site-packages/airflow/task/task_runner/standard_task_runner.py", line 117, in _start_by_fork
    ret = args.func(args, dag=self.dag)
          ^^^^^^^^^^^^^^^^^^^^^^^^^^^^^
  File "/home/airflow/.local/lib/python3.12/site-packages/airflow/cli/cli_config.py", line 49, in command
    return func(*args, **kwargs)
           ^^^^^^^^^^^^^^^^^^^^^
  File "/home/airflow/.local/lib/python3.12/site-packages/airflow/utils/cli.py", line 116, in wrapper
    return f(*args, **kwargs)
           ^^^^^^^^^^^^^^^^^^
  File "/home/airflow/.local/lib/python3.12/site-packages/airflow/cli/commands/task_command.py", line 483, in task_run
    task_return_code = _run_task_by_selected_method(args, _dag, ti)
                       ^^^^^^^^^^^^^^^^^^^^^^^^^^^^^^^^^^^^^^^^^^^^
  File "/home/airflow/.local/lib/python3.12/site-packages/airflow/cli/commands/task_command.py", line 256, in _run_task_by_selected_method
    return _run_raw_task(args, ti)
           ^^^^^^^^^^^^^^^^^^^^^^^
  File "/home/airflow/.local/lib/python3.12/site-packages/airflow/cli/commands/task_command.py", line 341, in _run_raw_task
    return ti._run_raw_task(
           ^^^^^^^^^^^^^^^^^
  File "/home/airflow/.local/lib/python3.12/site-packages/airflow/utils/session.py", line 97, in wrapper
    return func(*args, session=session, **kwargs)
           ^^^^^^^^^^^^^^^^^^^^^^^^^^^^^^^^^^^^^^
  File "/home/airflow/.local/lib/python3.12/site-packages/airflow/models/taskinstance.py", line 3006, in _run_raw_task
    return _run_raw_task(
           ^^^^^^^^^^^^^^
  File "/home/airflow/.local/lib/python3.12/site-packages/airflow/models/taskinstance.py", line 274, in _run_raw_task
    TaskInstance._execute_task_with_callbacks(
  File "/home/airflow/.local/lib/python3.12/site-packages/airflow/models/taskinstance.py", line 3161, in _execute_task_with_callbacks
    result = self._execute_task(context, task_orig)
             ^^^^^^^^^^^^^^^^^^^^^^^^^^^^^^^^^^^^^^
  File "/home/airflow/.local/lib/python3.12/site-packages/airflow/models/taskinstance.py", line 3185, in _execute_task
    return _execute_task(self, context, task_orig)
           ^^^^^^^^^^^^^^^^^^^^^^^^^^^^^^^^^^^^^^^
  File "/home/airflow/.local/lib/python3.12/site-packages/airflow/models/taskinstance.py", line 768, in _execute_task
    result = _execute_callable(context=context, **execute_callable_kwargs)
             ^^^^^^^^^^^^^^^^^^^^^^^^^^^^^^^^^^^^^^^^^^^^^^^^^^^^^^^^^^^^^
  File "/home/airflow/.local/lib/python3.12/site-packages/airflow/models/taskinstance.py", line 734, in _execute_callable
    return ExecutionCallableRunner(
           ^^^^^^^^^^^^^^^^^^^^^^^^
  File "/home/airflow/.local/lib/python3.12/site-packages/airflow/utils/operator_helpers.py", line 252, in run
    return self.func(*args, **kwargs)
           ^^^^^^^^^^^^^^^^^^^^^^^^^^
  File "/home/airflow/.local/lib/python3.12/site-packages/airflow/models/baseoperator.py", line 424, in wrapper
    return func(self, *args, **kwargs)
           ^^^^^^^^^^^^^^^^^^^^^^^^^^^
  File "/home/airflow/.local/lib/python3.12/site-packages/airflow/operators/python.py", line 238, in execute
    return_value = self.execute_callable()
                   ^^^^^^^^^^^^^^^^^^^^^^^
  File "/home/airflow/.local/lib/python3.12/site-packages/airflow/operators/python.py", line 256, in execute_callable
    return runner.run(*self.op_args, **self.op_kwargs)
           ^^^^^^^^^^^^^^^^^^^^^^^^^^^^^^^^^^^^^^^^^^^
  File "/home/airflow/.local/lib/python3.12/site-packages/airflow/utils/operator_helpers.py", line 252, in run
    return self.func(*args, **kwargs)
           ^^^^^^^^^^^^^^^^^^^^^^^^^^
  File "/opt/airflow/dags/data-eng-dag-etl/dag.py", line 50, in creating_ddl
    column_name = input_str[0].split('|')
                  ^^^^^^^^^^^^^^^^^^
AttributeError: 'tuple' object has no attribute 'split'
[2025-03-24T16:08:19.457+0000] {local_task_job_runner.py:266} INFO - Task exited with return code 1
[2025-03-24T16:08:19.493+0000] {taskinstance.py:3901} INFO - 0 downstream tasks scheduled from follow-on schedule check
[2025-03-24T16:08:19.499+0000] {local_task_job_runner.py:245} INFO - ::endgroup::
